Workbook

Sheet Dashboard
A1: แผนพัฒนาแพลตฟอร์ม PDPA 15 โมดูล — ภาพรวม (PM / SA) | Next.js + Go
A2: สร้างจากรายการฟังก์ชัน 243 ข้อ + ผลเทียบ OneTrust + ระบบจัดการผู้ใช้และสิทธิ์ | ตัวเลขทั้งหมดคำนวณจากชีตอื่น
A4: ตัวชี้วัด | B4: ค่า
A5: จำนวน Feature ใน WBS ทั้งหมด | B5: =COUNTA(WBS!A5:A279) -> 275
A6: ฟังก์ชันจากรายการ 243 ข้อที่มีงานรองรับ | B6: =COUNTIF(Traceability!J5:J247,"✓") -> 243
A7: Feature ที่ PM/SA เพิ่ม (บริการกลาง + User & Permission) | B7: =COUNTIF(WBS!F5:F279,"เพิ่มโดย PM/SA") -> 32
A8: Must / Should / Nice-to-have | B8: =COUNTIF(WBS!G5:G279,"Must")&" / "&COUNTIF(WBS!G5:G279,"Should")&" / "&COUNTIF(WBS!G5:G279,"Nice-to-have") -> 140 / 112 / 23
A9: Feature ของระบบจัดการผู้ใช้และสิทธิ์ (Epic IAM) | B9: =COUNTIF(WBS!B5:B279,"IAM") -> 21
A10: Feature ที่ OneTrust ไม่มี (จุดต่าง) | B10: =COUNTIF(WBS!V5:V279,"ไม่มี") -> 24
A11: จำนวน Task ทั้งหมด (Task_List) | B11: =COUNTA(Task_List!A5:A1310) -> 1306
A12: Effort รวม (man-day) | B12: =Roadmap!L10 -> 4287.2
A13: Effort รวม + contingency (man-day) | B13: =Roadmap!M10 -> 4930.28
A14: ระยะเวลารวม (sprint) | B14: =Roadmap!N10 -> 32
A15: ระยะเวลารวม (เดือน โดยประมาณ) | B15: =Roadmap!S10 -> 14.7
A16: วันเริ่มโครงการ | B16: =Roadmap!Q10 -> 46328
A17: MVP go-live (สิ้นสุด P1) | B17: =Roadmap!R6 -> 46535
A18: เสร็จครบทุก Phase | B18: =Roadmap!R10 -> 46773
A19: ทีมสูงสุด (คน, ไม่รวม Legal/Doc) | B19: =MAX(SUM(Assumptions!$B$23,Assumptions!$B$24,Assumptions!$B$25,Assumptions!$B$26,Assumptions!$B$27,Assumptions!$B$28,Assumptions!$B$29),SUM(Assumptions!$C$23,Assumptions!$C$24,Assumptions!$C$25,Assumptions!$C$26,Assumptions!$C$27,Assumptions!$C$28,Assumptions!$C$29),SUM(Assumptions!$D$23,Assumptions!$D$24,Assumptions!$D$25,Assumptions!$D$26,Assumptions!$D$27,Assumptions!$D$28,Assumptions!$D$29),SUM(Assumptions!$E$23,Assumptions!$E$24,Assumptions!$E$25,Assumptions!$E$26,Assumptions!$E$27,Assumptions!$E$28,Assumptions!$E$29),SUM(Assumptions!$F$23,Assumptions!$F$24,Assumptions!$F$25,Assumptions!$F$26,Assumptions!$F$27,Assumptions!$F$28,Assumptions!$F$29)) -> 25
A20: งบตาม effort (บาท, รวม contingency) | B20: =Roadmap!T10 -> 28847808
A21: งบทีมเต็มเวลา (บาท) | B21: =Roadmap!U10 -> 44020000
A23: สรุปราย Phase
A24: Phase | B24: man-day (รวม contingency) | C24: Sprints | D24: เริ่ม | E24: สิ้นสุด | F24: งบทีมเต็มเวลา (บาท) | G24: คอขวด
A25: P0 – Foundation + User & Permission | B25: =Roadmap!M5 -> 817.535 | C25: =Roadmap!N5 -> 6 | D25: =Roadmap!Q5 -> 46328 | E25: =Roadmap!R5 -> 46409 | F25: =Roadmap!U5 -> 8205000 | G25: =Roadmap!V5 -> BE
A26: P1 – MVP กฎหมายหลัก | B26: =Roadmap!M6 -> 1604.71 | C26: =Roadmap!N6 -> 9 | D26: =Roadmap!Q6 -> 46412 | E26: =Roadmap!R6 -> 46535 | F26: =Roadmap!U6 -> 13657500 | G26: =Roadmap!V6 -> FE
A27: P2 – Governance & คู่ค้า | B27: =Roadmap!M7 -> 778.895 | C27: =Roadmap!N7 -> 5 | D27: =Roadmap!Q7 -> 46538 | E27: =Roadmap!R7 -> 46605 | F27: =Roadmap!U7 -> 6987500 | G27: =Roadmap!V7 -> FE
A28: P3 – Should | B28: =Roadmap!M8 -> 1352.86 | C28: =Roadmap!N8 -> 8 | D28: =Roadmap!Q8 -> 46608 | E28: =Roadmap!R8 -> 46717 | F28: =Roadmap!U8 -> 11180000 | G28: =Roadmap!V8 -> FE
A29: P4 – Nice-to-have + AI | B29: =Roadmap!M9 -> 376.28 | C29: =Roadmap!N9 -> 4 | D29: =Roadmap!Q9 -> 46720 | E29: =Roadmap!R9 -> 46773 | F29: =Roadmap!U9 -> 3990000 | G29: =Roadmap!V9 -> QA
A31: ข้อสังเกตของ PM / SA
A32: • บริการกลาง (Epic PLT) เป็นฐานของทุกโมดูล — workflow/SLA, form engine, document composer, versioning/approval และ audit ใช้ร่วม 10+ โมดูล จึงอยู่ใน P0 และต้นของ P1
A33: • User & Permission (Epic IAM): Keycloak ดูแล login / SSO / MFA ส่วน RBAC + ขอบเขตข้อมูลตามหน่วยงานเขียนใน Go และตรวจทุก endpoint ผ่าน x-permission ใน OpenAPI; SSO/ThaID และการปกปิด PII ดึงเข้า P1
A34: • จุดต่างจาก OneTrust ที่ควรส่งให้ถึงมือลูกค้าเร็ว: DSA/DPA generator (agreement engine เดียว), คลัง RoPA มาตรฐานภาษาไทย, wizard ประกาศ + checklist ม.23, แจ้งเหตุล่าช้า 15 วัน, data center ในไทย
A35: • ความเสี่ยงที่ต้องจัดการก่อนเริ่ม: หา tech lead Go / Next.js, PoC Keycloak multi-tenant และ ThaID, ย้าย business rule ของระบบ Consent เดิม (FSD V3.2)
A36: • ปรับกำลังคนราย phase ที่ชีต Assumptions แล้วดูคอลัมน์ 'คอขวด' และตาราง Utilization ในชีต Roadmap เพื่อหาจุดสมดุลระหว่างเวลาและงบ
A38: วิธีใช้ไฟล์
A39: • ปรับจำนวนคนราย phase อัตราค่าแรง และสัดส่วน SA/UX/QA ที่ชีต Assumptions → ระยะเวลา งบ และ timeline คำนวณใหม่อัตโนมัติ
A40: • ปรับขนาดงาน (XS-XL), Priority หรือย้าย Phase ของฟีเจอร์ที่ชีต WBS (ช่องสีเหลือง); คอลัมน์ OneTrust ช่วยจัดลำดับจุดต่าง
A41: • ชีต Task_List แตกทุกฟีเจอร์เป็นงานราย role (SA / UX / BE-Go / FE-Next.js / QA) พร้อม dependency — ใส่ Sprint และผู้รับผิดชอบได้ แล้ว import เข้า Jira
A42: • ชีต Roles_Permissions คือแบบร่าง Role (16 บทบาท), Permission matrix และนโยบายความปลอดภัย สำหรับยืนยันกับลูกค้าใน T06
A43: • ชีต Architecture มีแผนภาพ ADR และ mapping Epic → Go package / Next.js route; ชีต Traceability ยืนยันว่าฟังก์ชันทั้ง 243 ข้อมีงานรองรับ

Sheet Assumptions
A1: สมมติฐานและพารามิเตอร์การประมาณการ
A2: ช่องสีเหลืองแก้ได้ — ทุกชีตคำนวณใหม่อัตโนมัติ
A4: พารามิเตอร์ | B4: ค่า | C4: คำอธิบาย
A5: วันทำงานต่อ Sprint | B5: 10 | C5: sprint ละ 2 สัปดาห์
A6: Focus factor | B6: 0.8 | C6: สัดส่วนเวลาที่ใช้พัฒนาได้จริง (หักประชุม วันหยุด ลา)
A7: Contingency | B7: 0.15 | C7: เผื่อความไม่แน่นอนของประมาณการ
A8: SA (% ของ BE+FE) | B8: 0.12 | C8: วิเคราะห์ business rules, ERD, OpenAPI spec ต่อฟีเจอร์
A9: UX (% ของ FE เฉพาะฟีเจอร์ที่มีหน้าจอใหม่) | B9: 0.4 | C9: ใช้กับฟีเจอร์ที่ช่อง UX = Y
A10: QA (% ของ BE+FE) | B10: 0.35 | C10: test case, automated test (Go API / Playwright), regression
A11: PM: วันต่อ Sprint สำหรับงานบริหารต่อเนื่อง | B11: 3 | C11: ceremonies, status report, steering, risk / issue
A12: วันเริ่มโครงการ | B12: 46328 | C12: วันจันทร์แรกของ sprint 1
A13: DevOps: วันต่อ Sprint สำหรับงานต่อเนื่อง | B13: 5 | C13: ดูแล environment, release, monitoring, on-call (ไม่นำไปคำนวณระยะเวลา)
A14: ขนาดงาน (Size) | B14: Dev-days | C14: ตัวอย่าง
A15: XS | B15: 1 | C15: เพิ่มฟิลด์ / ปรับเล็กน้อย / ใช้บริการกลางเกือบทั้งหมด
A16: S | B16: 3 | C16: CRUD หน้าจอเดียว
A17: M | B17: 5 | C17: มี logic หรือหลายหน้าจอ
A18: L | B18: 10 | C18: ซับซ้อน มี integration หรือ engine ย่อย
A19: XL | B19: 20 | C19: engine, SDK, scanner, diagram
A20: - | B20: 0 | C20: ไม่มีงานส่วนนี้
A22: บทบาท | B22: คน P0 | C22: คน P1 | D22: คน P2 | E22: คน P3 | F22: คน P4 | G22: อัตรา (บาท/วัน) — ตัวอย่าง | H22: ใช้คำนวณระยะเวลา
A23: PM | B23: 1 | C23: 1 | D23: 1 | E23: 1 | F23: 1 | G23: 7000 | H23: ไม่ (ทำคู่ขนาน)
A24: SA | B24: 3 | C24: 2 | D24: 2 | E24: 2 | F24: 1 | G24: 7000 | H24: ใช่ (คอขวด)
A25: UX/UI | B25: 2 | C25: 2 | D25: 1 | E25: 1 | F25: 1 | G25: 5500 | H25: ใช่ (คอขวด)
A26: Backend (Go) | B26: 6 | C26: 7 | D26: 7 | E26: 7 | F26: 5 | G26: 6500 | H26: ใช่ (คอขวด)
A27: Frontend (Next.js) | B27: 4 | C27: 6 | D27: 6 | E27: 6 | F27: 4 | G27: 5500 | H27: ใช่ (คอขวด)
A28: QA | B28: 4 | C28: 5 | D28: 5 | E28: 5 | F28: 3 | G28: 4500 | H28: ใช่ (คอขวด)
A29: DevOps | B29: 2 | C29: 2 | D29: 1 | E29: 1 | F29: 1 | G29: 6500 | H29: ใช่ (คอขวด)
A30: Legal/DPO | B30: 0.5 | C30: 0.5 | D30: 0.5 | E30: 0.5 | F30: 0.5 | G30: 8000 | H30: ไม่ (ทำคู่ขนาน)
A31: Technical writer | B31: 0.5 | C31: 0.5 | D31: 0.5 | E31: 0.5 | F31: 0.5 | G31: 3500 | H31: ไม่ (ทำคู่ขนาน)
A32: กำลังคนปรับได้ราย phase (ramp-up / ramp-down) — PM, Legal/DPO และ Doc ไม่ใช้คำนวณระยะเวลาแต่ใช้คำนวณงบ
A34: สมมติฐานและนอกขอบเขต
A35: • Stack: Next.js (App Router, TypeScript) สำหรับ admin และ portal; Go (modular monolith) + worker สำหรับ backend; PostgreSQL; Keycloak สำหรับ login/SSO/MFA; Valkey; object storage แบบ S3 — ฐานข้อมูลและ IdP เป็นสมมติฐานที่ปรับได้
A36: • ระบบ Consent เดิม (.NET + Blazor) ใช้เป็นต้นแบบ domain model และ test case ตาม FSD V3.2 แต่เขียนใหม่ด้วย Go; ย้ายข้อมูลเดิมผ่าน CON-22 และ T26
A37: • ฟังก์ชันทั้ง 243 ข้อจากไฟล์ 15 โมดูลอยู่ใน WBS ด้วยรหัสเดิม; ฟังก์ชันผู้ใช้และสิทธิ์ ORG-09 ถึง ORG-19 ย้ายมาอยู่ Epic IAM; PLT-xx และ IAM-xx คือ feature ที่ PM/SA เพิ่มเพื่อให้สร้างได้จริง
A38: • หน่วยประมาณการคือ man-day; BE/FE รวม unit test แล้ว; SA, UX, QA คิดเป็นสัดส่วนของงาน dev ตามพารามิเตอร์ด้านบน
A39: • ระยะเวลาต่อ phase คำนวณจากบทบาทที่เป็นคอขวด (SA, UX, BE, FE, QA, DevOps) โดยไม่รวม PM, Legal, Doc ซึ่งทำงานคู่ขนาน
A40: • งานใน phase เดียวกันทำคู่ขนานได้ แต่ phase ถัดไปเริ่มหลัง phase ก่อนหน้าเสร็จ (แผนแบบอนุรักษ์) — ในทางปฏิบัติเริ่มวิเคราะห์ phase ถัดไปได้เร็วกว่านี้
A41: • เนื้อหากฎหมาย (template, คลังกิจกรรม, clause) จัดทำโดยบทบาท Legal/DPO ใน T15, T34, T40 — ระบบให้เฉพาะกลไก
A42: • ไม่รวม: ค่า cloud / hardware, ค่า pentest ภายนอก, ค่าที่ปรึกษากฎหมาย, ค่าบริการ e-signature / SMS / LLM, แอปมือถือเต็มรูปแบบ (มีเฉพาะ SDK), support 24x7
A43: • Mobile SDK (CON-07) ต้องใช้นักพัฒนา iOS / Android ซึ่งอยู่นอกทีม Next.js / Go — ประมาณการเป็นงาน FE และอาจจ้างภายนอก
...

Sheet WBS
A1: WBS — Epic / Feature พร้อมประมาณการ (man-day)
A2: ช่องสีเหลือง (Priority, Phase, ขนาดงาน BE/FE, UX) แก้ได้ | SA/UX/QA คำนวณจากสัดส่วนในชีต Assumptions | คอลัมน์ OneTrust มาจากไฟล์เปรียบเทียบ 15 โมดูล (สีแดง = จุดต่าง)
A4: ID | B4: Epic | C4: ชื่อ Epic | D4: ฟีเจอร์ (TH) | E4: Feature (EN) | F4: ที่มา / อ้างอิง | G4: Priority | H4: Phase | I4: งาน Backend (Go) | J4: งาน Frontend (Next.js) | K4: เกณฑ์การยอมรับ (AC) | L4: ขึ้นกับ | M4: BE size | N4: FE size | O4: UX | P4: BE (วัน) | Q4: FE (วัน) | R4: SA (วัน) | S4: UX (วัน) | T4: QA (วัน) | U4: รวม (วัน) | V4: OneTrust | W4: หมายเหตุ
A5: PLT-01 | B5: PLT | C5: โครงสร้างพื้นฐานแพลตฟอร์ม (Platform Foundation) | D5: โครงระบบ Go modular monolith + Next.js monorepo | E5: Solution skeleton | F5: เพิ่มโดย PM/SA | G5: Must | H5: P0 | I5: โครง backend/internal/<module>, chi router + oapi-codegen (OpenAPI-first), pgx + sqlc, goose migration, config, error model RFC 9457, health/readiness, graceful shutdown; binary api / worker / scanner | J5: Turborepo + pnpm: apps/admin, apps/portal (App Router, TypeScript), packages/ui (shadcn/ui + Tailwind), api-client generate จาก OpenAPI, layout และเมนูตามสิทธิ์ | K5: สร้างโมดูลใหม่จาก template ได้ภายใน 1 วัน; แก้ OpenAPI แล้ว Go stub และ TS client generate ใน CI | L5: T04, T05 | M5: L | N5: M | O5: N | P5: =IFERROR(VLOOKUP($M5,Assumptions!$A$15:$B$20,2,FALSE()),0) -> 10 | Q5: =IFERROR(VLOOKUP($N5,Assumptions!$A$15:$B$20,2,FALSE()),0) -> 5 | R5: =ROUND((P5+Q5)*Assumptions!$B$8,1) -> 1.8 | S5: =IF($O5="Y",ROUND(Q5*Assumptions!$B$9,1),0) -> 0 | T5: =ROUND((P5+Q5)*Assumptions!$B$10,1) -> 5.3 | U5: =SUM(P5:T5) -> 22.1 | V5: -
A6: PLT-02 | B6: PLT | C6: โครงสร้างพื้นฐานแพลตฟอร์ม (Platform Foundation) | D6: Multi-tenant และการแยกข้อมูล | E6: Multi-tenancy & isolation | F6: เพิ่มโดย PM/SA | G6: Must | H6: P0 | I6: tenant registry, resolver จาก subdomain / custom domain / token, tenant_id ทุกตาราง + PostgreSQL RLS (SET app.tenant_id ต่อ transaction), provisioning (master data, role มาตรฐาน), โหมด DB แยกต่อ tenant | J6: tenant context ใน middleware ของ Next.js, custom domain ของ portal | K6: ผู้ใช้ tenant A เข้าถึงข้อมูล tenant B ไม่ได้แม้เรียก API ตรง (automated test ทุก endpoint) | L6: PLT-01 | M6: L | N6: S | O6: N | P6: =IFERROR(VLOOKUP($M6,Assumptions!$A$15:$B$20,2,FALSE()),0) -> 10 | Q6: =IFERROR(VLOOKUP($N6,Assumptions!$A$15:$B$20,2,FALSE()),0) -> 3 | R6: =ROUND((P6+Q6)*Assumptions!$B$8,1) -> 1.6 | S6: =IF($O6="Y",ROUND(Q6*Assumptions!$B$9,1),0) -> 0 | T6: =ROUND((P6+Q6)*Assumptions!$B$10,1) -> 4.6 | U6: =SUM(P6:T6) -> 19.2 | V6: -
A7: PLT-03 | B7: PLT | C7: โครงสร้างพื้นฐานแพลตฟอร์ม (Platform Foundation) | D7: ระบบหลายภาษา TH/EN | E7: Localization (i18n) | F7: เพิ่มโดย PM/SA | G7: Must | H7: P0 | I7: ตาราง translation สำหรับเนื้อหาที่ผู้ใช้สร้าง (ข้อความยินยอม ประกาศ template), Accept-Language, fallback | J7: next-intl ข้อความ UI TH/EN, วันที่ พ.ศ. / ค.ศ., เขตเวลา Asia/Bangkok, ฟอนต์ไทย | K7: ทุกหน้าสลับ TH/EN ได้ และวันที่แสดง พ.ศ. ตามการตั้งค่า | L7: PLT-01 | M7: S | N7: M | O7: N | P7: =IFERROR(VLOOKUP($M7,Assumptions!$A$15:$B$20,2,FALSE()),0) -> 3 | Q7: =IFERROR(VLOOKUP($N7,Assumptions!$A$15:$B$20,2,FALSE()),0) -> 5 | R7: =ROUND((P7+Q7)*Assumptions!$B$8,1) -> 1 | S7: =IF($O7="Y",ROUND(Q7*Assumptions!$B$9,1),0) -> 0 | T7: =ROUND((P7+Q7)*Assumptions!$B$10,1) -> 2.8 | U7: =SUM(P7:T7) -> 11.8 | V7: -
A8: PLT-04 | B8: PLT | C8: โครงสร้างพื้นฐานแพลตฟอร์ม (Platform Foundation) | D8: บริการแจ้งเตือน Email / SMS / LINE / In-app | E8: Notification service | F8: เพิ่มโดย PM/SA | G8: Must | H8: P0 | I8: template มีตัวแปร (TH/EN), adapter SMTP/SES, SMS gateway ไทย, LINE Messaging API, in-app ผ่าน SSE, ส่งผ่าน River + retry, delivery log, quiet hours | J8: หน้าจัดการ template พร้อม preview, กระดิ่งแจ้งเตือนใน admin, หน้าสถานะการส่ง | K8: ส่งล้มเหลวมี retry อัตโนมัติ และตรวจสถานะรายข้อความได้ | L8: PLT-10 | M8: L | N8: M | O8: Y | P8: =IFERROR(VLOOKUP($M8,Assumptions!$A$15:$B$20,2,FALSE()),0) -> 10 | Q8: =IFERROR(VLOOKUP($N8,Assumptions!$A$15:$B$20,2,FALSE()),0) -> 5 | R8: =ROUND((P8+Q8)*Assumptions!$B$8,1) -> 1.8 | S8: =IF($O8="Y",ROUND(Q8*Assumptions!$B$9,1),0) -> 2 | T8: =ROUND((P8+Q8)*Assumptions!$B$10,1) -> 5.3 | U8: =SUM(P8:T8) -> 24.1 | V8: -
A9: PLT-05 | B9: PLT | C9: โครงสร้างพื้นฐานแพลตฟอร์ม (Platform Foundation) | D9: Workflow & SLA engine | E9: Workflow / SLA engine | F9: เพิ่มโดย PM/SA | G9: Must | H9: P0 | I9: state machine กำหนดได้ต่อ tenant (JSON definition), มอบหมายคน/กลุ่ม, SLA timer แบบวันปฏิทิน / วันทำการ / ชั่วโมง พร้อมวันหยุดไทย, reminder และ escalation ด้วย River scheduled job, comment, history | J9: component กระดานงาน, timeline, ป้าย SLA, หน้าตั้งค่า workflow แบบฟอร์ม | K9: นับ SLA ถูกต้องเมื่อข้ามวันหยุด และแจ้งเตือนก่อนครบกำหนดตามที่ตั้ง (unit test ครอบคลุมกรณีข้ามวันหยุด) | L9: PLT-10, ORG-20 | M9: XL | N9: M | O9: Y | P9: =IFERROR(VLOOKUP($M9,Assumptions!$A$15:$B$20,2,FALSE()),0) -> 20 | Q9: =IFERROR(VLOOKUP($N9,Assumptions!$A$15:$B$20,2,FALSE()),0) -> 5 | R9: =ROUND((P9+Q9)*Assumptions!$B$8,1) -> 3 | S9: =IF($O9="Y",ROUND(Q9*Assumptions!$B$9,1),0) -> 2 | T9: =ROUND((P9+Q9)*Assumptions!$B$10,1) -> 8.8 | U9: =SUM(P9:T9) -> 38.8 | V9: - | W9: บริการกลางที่ DSAR, Breach, DPIA, Vendor และ Tasks ใช้
A10: PLT-06 | B10: PLT | C10: โครงสร้างพื้นฐานแพลตฟอร์ม (Platform Foundation) | D10: Form & assessment engine | E10: Dynamic form & assessment engine | F10: เพิ่มโดย PM/SA | G10: Must | H10: P0 | I10: form schema มีเวอร์ชัน (JSON), ประเภทคำถาม, conditional logic, คะแนน/น้ำหนัก, validation ฝั่ง server, คำตอบ JSONB, มอบหมายผู้ตอบรายส่วน | J10: Form builder ลากวาง (dnd-kit) + renderer ใช้ร่วม admin และ portal (react-hook-form + zod), preview หลายภาษา | K10: สร้างแบบประเมินที่มีเงื่อนไขซ่อน/แสดงและคิดคะแนนได้โดยไม่เขียนโค้ด; ทุกโมดูลใช้ renderer เดียวกัน | L10: PLT-01 | M10: L | N10: XL | O10: Y | P10: =IFERROR(VLOOKUP($M10,Assumptions!$A$15:$B$20,2,FALSE()),0) -> 10 | Q10: =IFERROR(VLOOKUP($N10,Assumptions!$A$15:$B$20,2,FALSE()),0) -> 20 | R10: =ROUND((P10+Q10)*Assumptions!$B$8,1) -> 3.6 | S10: =IF($O10="Y",ROUND(Q10*Assumptions!$B$9,1),0) -> 8 | T10: =ROUND((P10+Q10)*Assumptions!$B$10,1) -> 10.5 | U10: =SUM(P10:T10) -> 52.1 | V10: - | W10: ใช้ร่วม: ฟอร์มความยินยอม, คำขอใช้สิทธิ, แจ้งเหตุ, DPIA, คู่ค้า, RoPA, checklist
A11: PLT-07 | B11: PLT | C11: โครงสร้างพื้นฐานแพลตฟอร์ม (Platform Foundation) | D11: ความเห็น ไฟล์แนบ และไทม์ไลน์กิจกรรม | E11: Collaboration components | F11: เพิ่มโดย PM/SA | G11: Must | H11: P0 | I11: comment + @mention, ไฟล์แนบ, activity feed ต่อ record แบบ polymorphic, แจ้งเตือนผู้เกี่ยวข้อง | J11: component ความเห็น / ไฟล์แนบ / ไทม์ไลน์ ใช้ร่วมทุกโมดูล | K11: ทุกโมดูลใช้ component เดียวกัน และการ mention ส่งแจ้งเตือน | L11: PLT-09, PLT-12 | M11: M | N11: M | O11: Y | P11: =IFERROR(VLOOKUP($M11,Assumptions!$A$15:$B$20,2,FALSE()),0) -> 5 | Q11: =IFERROR(VLOOKUP($N11,Assumptions!$A$15:$B$20,2,FALSE()),0) -> 5 | R11: =ROUND((P11+Q11)*Assumptions!$B$8,1) -> 1.2 | S11: =IF($O11="Y",ROUND(Q11*Assumptions!$B$9,1),0) -> 2 | T11: =ROUND((P11+Q11)*Assumptions!$B$10,1) -> 3.5 | U11: =SUM(P11:T11) -> 16.7 | V11: -
A12: PLT-08 | B12: PLT | C12: โครงสร้างพื้นฐานแพลตฟอร์ม (Platform Foundation) | D12: เวอร์ชันและการอนุมัติ | E12: Versioning & approval framework | F12: เพิ่มโดย PM/SA | G12: Must | H12: P0 | I12: snapshot + diff ของ record, สถานะ ร่าง → รอตรวจ → อนุมัติ → เผยแพร่, ผู้อนุมัติหลายระดับ, maker-checker | J12: แถบสถานะเวอร์ชัน, หน้าเปรียบเทียบเวอร์ชัน, กล่องงานรออนุมัติ | K12: record ที่เผยแพร่แล้วแก้ไม่ได้ต้องสร้างเวอร์ชันใหม่; ผู้สร้างอนุมัติงานของตนเองไม่ได้ | L12: PLT-05, PLT-07 | M12: M | N12: M | O12: Y | P12: =IFERROR(VLOOKUP($M12,Assumptions!$A$15:$B$20,2,FALSE()),0) -> 5 | Q12: =IFERROR(VLOOKUP($N12,Assumptions!$A$15:$B$20,2,FALSE()),0) -> 5 | R12: =ROUND((P12+Q12)*Assumptions!$B$8,1) -> 1.2 | S12: =IF($O12="Y",ROUND(Q12*Assumptions!$B$9,1),0) -> 2 | T12: =ROUND((P12+Q12)*Assumptions!$B$10,1) -> 3.5 | U12: =SUM(P12:T12) -> 16.7 | V12: -
A13: PLT-09 | B13: PLT | C13: โครงสร้างพื้นฐานแพลตฟอร์ม (Platform Foundation) | D13: จัดเก็บไฟล์และสแกนไวรัส | E13: File storage & AV scan | F13: เพิ่มโดย PM/SA | G13: Must | H13: P0 | I13: S3 API (S3 / SeaweedFS / MinIO), เข้ารหัส, ClamAV, จำกัดชนิดและขนาด, pre-signed URL หมดอายุ, อายุไฟล์ | J13: component อัปโหลด / ดาวน์โหลด (ลากวาง, progress) | K13: ไฟล์ติดไวรัสถูกปฏิเสธ และลิงก์ดาวน์โหลดหมดอายุตามเวลาที่ตั้ง | L13: PLT-01 | M13: M | N13: S | O13: N | P13: =IFERROR(VLOOKUP($M13,Assumptions!$A$15:$B$20,2,FALSE()),0) -> 5 | Q13: =IFERROR(VLOOKUP($N13,Assumptions!$A$15:$B$20,2,FALSE()),0) -> 3 | R13: =ROUND((P13+Q13)*Assumptions!$B$8,1) -> 1 | S13: =IF($O13="Y",ROUND(Q13*Assumptions!$B$9,1),0) -> 0 | T13: =ROUND((P13+Q13)*Assumptions!$B$10,1) -> 2.8 | U13: =SUM(P13:T13) -> 11.8 | V13: -
A14: PLT-10 | B14: PLT | C14: โครงสร้างพื้นฐานแพลตฟอร์ม (Platform Foundation) | D14: Background jobs และ scheduler | E14: Job queue & scheduler | F14: เพิ่มโดย PM/SA | G14: Must | H14: P0 | I14: River (job queue บน PostgreSQL): enqueue ใน transaction เดียวกับข้อมูล, retry/backoff, periodic job (cron), unique job, graceful shutdown ใน worker | J14: หน้าดูสถานะ job สำหรับผู้ดูแลระบบ | K14: job ที่ล้มเหลวมี retry และแจ้งเตือน; ไม่มี job ซ้ำเมื่อรันหลาย instance | L14: PLT-01 | M14: M | N14: S | O14: N | P14: =IFERROR(VLOOKUP($M14,Assumptions!$A$15:$B$20,2,FALSE()),0) -> 5 | Q14: =IFERROR(VLOOKUP($N14,Assumptions!$A$15:$B$20,2,FALSE()),0) -> 3 | R14: =ROUND((P14+Q14)*Assumptions!$B$8,1) -> 1 | S14: =IF($O14="Y",ROUND(Q14*Assumptions!$B$9,1),0) -> 0 | T14: =ROUND((P14+Q14)*Assumptions!$B$10,1) -> 2.8 | U14: =SUM(P14:T14) -> 11.8 | V14: -
A15: PLT-11 | B15: PLT | C15: โครงสร้างพื้นฐานแพลตฟอร์ม (Platform Foundation) | D15: Domain events และ outbox | E15: Domain events & outbox | F15: เพิ่มโดย PM/SA | G15: Must | H15: P0 | I15: transactional outbox, event catalog (consent.changed, ropa.updated, dsar.closed ฯลฯ), subscriber ภายใน, ส่งต่อ webhook / NATS | J15: - | K15: event ไม่สูญหายเมื่อระบบล่มกลางคัน (at-least-once + idempotent consumer) | L15: PLT-10 | M15: M | N15: - | O15: N | P15: =IFERROR(VLOOKUP($M15,Assumptions!$A$15:$B$20,2,FALSE()),0) -> 5 | Q15: =IFERROR(VLOOKUP($N15,Assumptions!$A$15:$B$20,2,FALSE()),0) -> 0 | R15: =ROUND((P15+Q15)*Assumptions!$B$8,1) -> 0.6 | S15: =IF($O15="Y",ROUND(Q15*Assumptions!$B$9,1),0) -> 0 | T15: =ROUND((P15+Q15)*Assumptions!$B$10,1) -> 1.8 | U15: =SUM(P15:T15) -> 7.4 | V15: - | W15: ใช้เชื่อมโมดูลกัน เช่น ROPA-19, DSAR-21, DFG-02
A16: PLT-12 | B16: PLT | C16: โครงสร้างพื้นฐานแพลตฟอร์ม (Platform Foundation) | D16: โครงสร้าง Audit log | E16: Tamper-evident audit log | F16: เพิ่มโดย PM/SA | G16: Must | H16: P0 | I16: event แบบ append-only + hash chain ต่อ tenant, before/after (JSON diff), ผู้ทำ, IP, user agent, partition รายเดือน, นโยบายระยะเวลาเก็บ | J16: - | K16: แก้ log ย้อนหลังแล้วการตรวจ hash chain ล้มเหลว | L16: PLT-01 | M16: M | N16: - | O16: N | P16: =IFERROR(VLOOKUP($M16,Assumptions!$A$15:$B$20,2,FALSE()),0) -> 5 | Q16: =IFERROR(VLOOKUP($N16,Assumptions!$A$15:$B$20,2,FALSE()),0) -> 0 | R16: =ROUND((P16+Q16)*Assumptions!$B$8,1) -> 0.6 | S16: =IF($O16="Y",ROUND(Q16*Assumptions!$B$9,1),0) -> 0 | T16: =ROUND((P16+Q16)*Assumptions!$B$10,1) -> 1.8 | U16: =SUM(P16:T16) -> 7.4 | V16: - | W16: หน้าดู log คือ ORG-19
A17: PLT-13 | B17: PLT | C17: โครงสร้างพื้นฐานแพลตฟอร์ม (Platform Foundation) | D17: เข้ารหัสข้อมูลส่วนบุคคลระดับฟิลด์ | E17: PII encryption & key management | F17: เพิ่มโดย PM/SA | G17: Must | H17: P0 | I17: envelope encryption (DEK ต่อ tenant, KEK ใน KMS / OpenBao Transit), blind index (HMAC) สำหรับค้นหาอีเมล / เบอร์ / เลขบัตร, key rotation | J17: - | K17: identifier ในฐานข้อมูลอ่านไม่ออกถ้าไม่มี key แต่ยังค้นหาแบบตรงตัวได้ | L17: PLT-01 | M17: M | N17: - | O17: N | P17: =IFERROR(VLOOKUP($M17,Assumptions!$A$15:$B$20,2,FALSE()),0) -> 5 | Q17: =IFERROR(VLOOKUP($N17,Assumptions!$A$15:$B$20,2,FALSE()),0) -> 0 | R17: =ROUND((P17+Q17)*Assumptions!$B$8,1) -> 0.6 | S17: =IF($O17="Y",ROUND(Q17*Assumptions!$B$9,1),0) -> 0 | T17: =ROUND((P17+Q17)*Assumptions!$B$10,1) -> 1.8 | U17: =SUM(P17:T17) -> 7.4 | V17: -
A18: PLT-14 | B18: PLT | C18: โครงสร้างพื้นฐานแพลตฟอร์ม (Platform Foundation) | D18: Import framework (Excel / CSV) | E18: Bulk import framework | F18: เพิ่มโดย PM/SA | G18: Must | H18: P0 | I18: import แบบ async: อ่าน Excel/CSV (excelize), map คอลัมน์, validate ทีละแถว, dry-run, รายงานข้อผิดพลาด, rollback | J18: wizard นำเข้า: อัปโหลด → map คอลัมน์ → ตรวจ → ยืนยัน | K18: นำเข้า 50,000 แถวได้ และได้ไฟล์รายงานแถวที่ผิดพร้อมเหตุผล | L18: PLT-10 | M18: M | N18: M | O18: Y | P18: =IFERROR(VLOOKUP($M18,Assumptions!$A$15:$B$20,2,FALSE()),0) -> 5 | Q18: =IFERROR(VLOOKUP($N18,Assumptions!$A$15:$B$20,2,FALSE()),0) -> 5 | R18: =ROUND((P18+Q18)*Assumptions!$B$8,1) -> 1.2 | S18: =IF($O18="Y",ROUND(Q18*Assumptions!$B$9,1),0) -> 2 | T18: =ROUND((P18+Q18)*Assumptions!$B$10,1) -> 3.5 | U18: =SUM(P18:T18) -> 16.7 | V18: - | W18: ใช้ร่วม ORG-08, ORG-09, ROPA-18, CON-22
A19: PLT-15 | B19: PLT | C19: โครงสร้างพื้นฐานแพลตฟอร์ม (Platform Foundation) | D19: Public API, webhook และ developer portal | E19: Public API & webhooks | F19: เพิ่มโดย PM/SA | G19: Must | H19: P0 | I19: versioning /v1, OpenAPI 3.1 + เอกสาร, rate limit ต่อ client (Valkey), idempotency key, webhook subscription + HMAC signature + retry / dead-letter | J19: หน้า developer: เอกสาร API, จัดการ webhook และดู delivery log | K19: client เกิน rate limit ได้ 429; webhook ที่ล้มเหลวถูกส่งซ้ำตามนโยบาย | L19: ORG-16, PLT-11 | M19: M | N19: S | O19: N | P19: =IFERROR(VLOOKUP($M19,Assumptions!$A$15:$B$20,2,FALSE()),0) -> 5 | Q19: =IFERROR(VLOOKUP($N19,Assumptions!$A$15:$B$20,2,FALSE()),0) -> 3 | R19: =ROUND((P19+Q19)*Assumptions!$B$8,1) -> 1 | S19: =IF($O19="Y",ROUND(Q19*Assumptions!$B$9,1),0) -> 0 | T19: =ROUND((P19+Q19)*Assumptions!$B$10,1) -> 2.8 | U19: =SUM(P19:T19) -> 11.8 | V19: -
A20: PLT-16 | B20: PLT | C20: โครงสร้างพื้นฐานแพลตฟอร์ม (Platform Foundation) | D20: Document composer (template + clause + merge field) | E20: Document composer | F20: เพิ่มโดย PM/SA | G20: Must | H20: P1 | I20: เก็บเอกสารเป็นโครงสร้าง (ProseMirror JSON) + merge field จากองค์กร / RoPA / คู่ค้า, คลัง clause มีเวอร์ชัน, render HTML → PDF ผ่าน Gotenberg (ฟอนต์ไทย) และสร้าง DOCX, diff ระหว่างเวอร์ชัน | J20: editor แบบ TipTap: บล็อก clause, merge field, สารบัญ, preview TH/EN, เปรียบเทียบเวอร์ชัน | K20: เอกสารภาษาไทยส่งออก PDF / Word ได้ตัวอักษรถูกต้อง และเปรียบเทียบสองเวอร์ชันได้ | L20: PLT-06, PLT-08 | M20: L | N20: L | O20: Y | P20: =IFERROR(VLOOKUP($M20,Assumptions!$A$15:$B$20,2,FALSE()),0) -> 10 | Q20: =IFERROR(VLOOKUP($N20,Assumptions!$A$15:$B$20,2,FALSE()),0) -> 10 | R20: =ROUND((P20+Q20)*Assumptions!$B$8,1) -> 2.4 | S20: =IF($O20="Y",ROUND(Q20*Assumptions!$B$9,1),0) -> 4 | T20: =ROUND((P20+Q20)*Assumptions!$B$10,1) -> 7 | U20: =SUM(P20:T20) -> 33.4 | V20: - | W20: ต้องเสร็จใน 2 sprint แรกของ P1; ใช้ร่วมประกาศ, หนังสือตอบคำขอ, แบบแจ้ง สคส., DPA, DSA
A21: PLT-17 | B21: PLT | C21: โครงสร้างพื้นฐานแพลตฟอร์ม (Platform Foundation) | D21: Public portal framework | E21: Public portal framework | F21: เพิ่มโดย PM/SA | G21: Must | H21: P1 | I21: route สาธารณะแยก, CAPTCHA, session ของเจ้าของข้อมูล (OTP / magic link), CSP และ rate limit | J21: apps/portal: theme ตามแบรนด์ tenant, custom domain, ISR/caching, WCAG 2.1 AA, TH/EN | K21: หน้า portal หลักผ่านการตรวจ accessibility ระดับ AA และโหลดเสร็จภายใน 2 วินาทีบน 4G | L21: PLT-02, IAM-05 | M21: M | N21: L | O21: Y | P21: =IFERROR(VLOOKUP($M21,Assumptions!$A$15:$B$20,2,FALSE()),0) -> 5 | Q21: =IFERROR(VLOOKUP($N21,Assumptions!$A$15:$B$20,2,FALSE()),0) -> 10 | R21: =ROUND((P21+Q21)*Assumptions!$B$8,1) -> 1.8 | S21: =IF($O21="Y",ROUND(Q21*Assumptions!$B$9,1),0) -> 4 | T21: =ROUND((P21+Q21)*Assumptions!$B$10,1) -> 5.3 | U21: =SUM(P21:T21) -> 26.1 | V21: -
A22: PLT-18 | B22: PLT | C22: โครงสร้างพื้นฐานแพลตฟอร์ม (Platform Foundation) | D22: Dashboard & report framework | E22: Reporting framework | F22: เพิ่มโดย PM/SA | G22: Must | H22: P1 | I22: query / aggregate API กรองตามสิทธิ์, export CSV / Excel (excelize) / PDF แบบ async + ศูนย์ดาวน์โหลด, ตั้งเวลาส่งรายงาน | J22: widget dashboard ปรับได้ (ECharts), ตัวกรองร่วม, data table (TanStack Table) + ปุ่ม export | K22: export 100,000 แถวแบบ async และแจ้งเมื่อไฟล์พร้อม; ตัวเลขตรงกับข้อมูลที่ผู้ใช้มีสิทธิ์เห็น | L22: PLT-10, IAM-02 | M22: L | N22: L | O22: Y | P22: =IFERROR(VLOOKUP($M22,Assumptions!$A$15:$B$20,2,FALSE()),0) -> 10 | Q22: =IFERROR(VLOOKUP($N22,Assumptions!$A$15:$B$20,2,FALSE()),0) -> 10 | R22: =ROUND((P22+Q22)*Assumptions!$B$8,1) -> 2.4 | S22: =IF($O22="Y",ROUND(Q22*Assumptions!$B$9,1),0) -> 4 | T22: =ROUND((P22+Q22)*Assumptions!$B$10,1) -> 7 | U22: =SUM(P22:T22) -> 33.4 | V22: -
A23: PLT-19 | B23: PLT | C23: โครงสร้างพื้นฐานแพลตฟอร์ม (Platform Foundation) | D23: Observability | E23: Observability | F23: เพิ่มโดย PM/SA | G23: Should | H23: P1 | I23: OpenTelemetry (trace / metric / log) ใน Go, Prometheus + Grafana + Loki, alert rules | J23: instrument Next.js (server + web vitals) | K23: มี dashboard สุขภาพระบบ และแจ้งเตือนเมื่อ error rate หรือ latency เกินเกณฑ์ | L23: PLT-01 | M23: S | N23: S | O23: N | P23: =IFERROR(VLOOKUP($M23,Assumptions!$A$15:$B$20,2,FALSE()),0) -> 3 | Q23: =IFERROR(VLOOKUP($N23,Assumptions!$A$15:$B$20,2,FALSE()),0) -> 3 | R23: =ROUND((P23+Q23)*Assumptions!$B$8,1) -> 0.7 | S23: =IF($O23="Y",ROUND(Q23*Assumptions!$B$9,1),0) -> 0 | T23: =ROUND((P23+Q23)*Assumptions!$B$10,1) -> 2.1 | U23: =SUM(P23:T23) -> 8.8 | V23: - | W23: ดึงเข้า P1 เพื่อพร้อม go-live
A24: PLT-20 | B24: PLT | C24: โครงสร้างพื้นฐานแพลตฟอร์ม (Platform Foundation) | D24: Connector framework | E24: Connector framework | F24: เพิ่มโดย PM/SA | G24: Should | H24: P3 | I24: Connector SDK ใน Go (test, discover, search subject, update / delete), credential เข้ารหัส, ตั้งเวลา; ชุดแรก PostgreSQL, MySQL, SQL Server, REST ทั่วไป | J24: หน้าจัดการ connector + ปุ่มทดสอบการเชื่อมต่อ | K24: เพิ่ม connector ใหม่ได้โดยไม่แก้โมดูลหลัก และทดสอบการเชื่อมต่อจากหน้าจอได้ | L24: PLT-11 | M24: L | N24: M | O24: Y | P24: =IFERROR(VLOOKUP($M24,Assumptions!$A$15:$B$20,2,FALSE()),0) -> 10 | Q24: =IFERROR(VLOOKUP($N24,Assumptions!$A$15:$B$20,2,FALSE()),0) -> 5 | R24: =ROUND((P24+Q24)*Assumptions!$B$8,1) -> 1.8 | S24: =IF($O24="Y",ROUND(Q24*Assumptions!$B$9,1),0) -> 2 | T24: =ROUND((P24+Q24)*Assumptions!$B$10,1) -> 5.3 | U24: =SUM(P24:T24) -> 24.1 | V24: - | W24: ใช้ร่วม DSAR-09, DSAR-12, DFG-09, DPX-13
A25: PLT-21 | B25: PLT | C25: โครงสร้างพื้นฐานแพลตฟอร์ม (Platform Foundation) | D25: ค้นหาข้ามระบบ | E25: Global search | F25: เพิ่มโดย PM/SA | G25: Should | H25: P3 | I25: ค้นหาข้าม entity ด้วย PostgreSQL pg_trgm (รองรับภาษาไทย) กรองตามสิทธิ์; ทางเลือก OpenSearch + Thai analyzer เมื่อข้อมูลโต | J25: ช่องค้นหากลาง (Cmd+K) + ผลลัพธ์แยกประเภท | K25: ผลค้นหาไม่แสดงข้อมูลที่ผู้ใช้ไม่มีสิทธิ์ | L25: IAM-02 | M25: M | N25: S | O25: N | P25: =IFERROR(VLOOKUP($M25,Assumptions!$A$15:$B$20,2,FALSE()),0) -> 5 | Q25: =IFERROR(VLOOKUP($N25,Assumptions!$A$15:$B$20,2,FALSE()),0) -> 3 | R25: =ROUND((P25+Q25)*Assumptions!$B$8,1) -> 1 | S25: =IF($O25="Y",ROUND(Q25*Assumptions!$B$9,1),0) -> 0 | T25: =ROUND((P25+Q25)*Assumptions!$B$10,1) -> 2.8 | U25: =SUM(P25:T25) -> 11.8 | V25: -
A26: PLT-22 | B26: PLT | C26: โครงสร้างพื้นฐานแพลตฟอร์ม (Platform Foundation) | D26: AI gateway | E26: AI gateway | F26: เพิ่มโดย PM/SA | G26: Nice-to-have | H26: P4 | I26: abstraction ผู้ให้บริการ LLM (API หรือ on-prem ผ่าน vLLM), ปกปิด PII ก่อนส่ง, prompt template มีเวอร์ชัน, โควตา / ค่าใช้จ่ายต่อ tenant, log เพื่อ audit, RAG ด้วย pgvector | J26: หน้าตั้งค่า AI ต่อ tenant (เปิด/ปิด, เลือก provider), ป้าย 'AI แนะนำ' + ปุ่มยืนยัน | K26: เมื่อเปิดโหมดปกปิด ไม่มีข้อมูลระบุตัวตนถูกส่งออกนอกระบบ; ผลจาก AI ต้องมีคนยืนยันก่อนบันทึก | L26: PLT-13 | M26: M | N26: S | O26: N | P26: =IFERROR(VLOOKUP($M26,Assumptions!$A$15:$B$20,2,FALSE()),0) -> 5 | Q26: =IFERROR(VLOOKUP($N26,Assumptions!$A$15:$B$20,2,FALSE()),0) -> 3 | R26: =ROUND((P26+Q26)*Assumptions!$B$8,1) -> 1 | S26: =IF($O26="Y",ROUND(Q26*Assumptions!$B$9,1),0) -> 0 | T26: =ROUND((P26+Q26)*Assumptions!$B$10,1) -> 2.8 | U26: =SUM(P26:T26) -> 11.8 | V26: - | W26: ใช้ร่วม DPIA-18, RTG-13, VEN-15, BRE-17, DPX-11
A27: IAM-01 | B27: IAM | C27: ระบบจัดการผู้ใช้และสิทธิ์ (User & Permission) | D27: Identity provider และ login flow | E27: Identity provider & login flow | F27: เพิ่มโดย PM/SA | G27: Must | H27: P0 | I27: ติดตั้ง Keycloak (HA), realm / Organizations ต่อ tenant, client ของ admin และ portal, Go middleware ตรวจ JWT (JWKS cache) + map ผู้ใช้ Keycloak ↔ ผู้ใช้ในระบบ, sync event เมื่อผู้ใช้ถูกปิด | J27: Auth.js (OIDC) แบบ BFF: session ใน httpOnly cookie, refresh token rotation, logout ทั้งระบบ (back-channel); theme หน้า login TH/EN ด้วย Keycloakify | K27: token ไม่ถูกเปิดเผยใน JavaScript ฝั่ง browser; logout แล้ว session ทุกแท็บสิ้นสุด | L27: PLT-01, PLT-02 | M27: L | N27: M | O27: Y | P27: =IFERROR(VLOOKUP($M27,Assumptions!$A$15:$B$20,2,FALSE()),0) -> 10 | Q27: =IFERROR(VLOOKUP($N27,Assumptions!$A$15:$B$20,2,FALSE()),0) -> 5 | R27: =ROUND((P27+Q27)*Assumptions!$B$8,1) -> 1.8 | S27: =IF($O27="Y",ROUND(Q27*Assumptions!$B$9,1),0) -> 2 | T27: =ROUND((P27+Q27)*Assumptions!$B$10,1) -> 5.3 | U27: =SUM(P27:T27) -> 24.1 | V27: -
A28: IAM-02 | B28: IAM | C28: ระบบจัดการผู้ใช้และสิทธิ์ (User & Permission) | D28: Permission engine (RBAC + data scope) | E28: Authorization engine | F28: เพิ่มโดย PM/SA | G28: Must | H28: P0 | I28: permission code module.resource.action, ประกาศสิทธิ์ต่อ endpoint ใน OpenAPI (x-permission) → middleware ตรวจอัตโนมัติ, deny by default, cache permission set ใน Valkey + invalidate ด้วย event, rule ระดับ record (owner / assignee) | J28: hook และ component <Can> ซ่อน/แสดงเมนูและปุ่ม, route guard ใน middleware ของ Next.js | K28: เรียก API ที่ไม่มีสิทธิ์ได้ 403 ทุก endpoint (contract test สร้างจาก OpenAPI) | L28: IAM-01 | M28: L | N28: M | O28: N | P28: =IFERROR(VLOOKUP($M28,Assumptions!$A$15:$B$20,2,FALSE()),0) -> 10 | Q28: =IFERROR(VLOOKUP($N28,Assumptions!$A$15:$B$20,2,FALSE()),0) -> 5 | R28: =ROUND((P28+Q28)*Assumptions!$B$8,1) -> 1.8 | S28: =IF($O28="Y",ROUND(Q28*Assumptions!$B$9,1),0) -> 0 | T28: =ROUND((P28+Q28)*Assumptions!$B$10,1) -> 5.3 | U28: =SUM(P28:T28) -> 22.1 | V28: -
A29: IAM-03 | B29: IAM | C29: ระบบจัดการผู้ใช้และสิทธิ์ (User & Permission) | D29: Console ผู้ให้บริการ: tenant และแพ็กเกจ | E29: Tenant & subscription admin | F29: เพิ่มโดย PM/SA | G29: Must | H29: P0 | I29: สร้าง / ระงับ tenant, แพ็กเกจและโมดูลที่เปิดใช้ (feature flag ตาม license), โควตา (ผู้ใช้ โดเมน ธุรกรรม), สร้างผู้ดูแล tenant คนแรก | J29: console สำหรับผู้ให้บริการแพลตฟอร์ม | K29: ปิดโมดูลที่ไม่ได้ซื้อแล้วเมนูและ API ของโมดูลนั้นใช้ไม่ได้ | L29: PLT-02 | M29: M | N29: M | O29: Y | P29: =IFERROR(VLOOKUP($M29,Assumptions!$A$15:$B$20,2,FALSE()),0) -> 5 | Q29: =IFERROR(VLOOKUP($N29,Assumptions!$A$15:$B$20,2,FALSE()),0) -> 5 | R29: =ROUND((P29+Q29)*Assumptions!$B$8,1) -> 1.2 | S29: =IF($O29="Y",ROUND(Q29*Assumptions!$B$9,1),0) -> 2 | T29: =ROUND((P29+Q29)*Assumptions!$B$10,1) -> 3.5 | U29: =SUM(P29:T29) -> 16.7 | V29: -
A30: ORG-09 | B30: IAM | C30: ระบบจัดการผู้ใช้และสิทธิ์ (User & Permission) | D30: จัดการผู้ใช้ | E30: User management | F30: 08_Organization | ประกาศมาตรการความปลอดภัย พ.ศ. 2565 | G30: Must | H30: P0 | I30: User API: เชิญทางอีเมล (สร้างผู้ใช้ใน Keycloak ผ่าน Admin API + ลิงก์ตั้งรหัสผ่าน), เปิด/ปิดบัญชี (ปิดใน Keycloak + revoke session), ผูกบริษัท/หน่วยงาน, นำเข้าผู้ใช้จาก Excel | J30: หน้ารายชื่อผู้ใช้ ค้นหา/กรอง, ฟอร์มเพิ่ม/แก้ไข, ส่งคำเชิญซ้ำ, นำเข้า | K30: ปิดบัญชีแล้ว session ถูกตัดภายใน 1 นาที และทุกการเปลี่ยนแปลงถูกบันทึก audit | L30: IAM-01, PLT-14 | M30: M | N30: M | O30: Y | P30: =IFERROR(VLOOKUP($M30,Assumptions!$A$15:$B$20,2,FALSE()),0) -> 5 | Q30: =IFERROR(VLOOKUP($N30,Assumptions!$A$15:$B$20,2,FALSE()),0) -> 5 | R30: =ROUND((P30+Q30)*Assumptions!$B$8,1) -> 1.2 | S30: =IF($O30="Y",ROUND(Q30*Assumptions!$B$9,1),0) -> 2 | T30: =ROUND((P30+Q30)*Assumptions!$B$10,1) -> 3.5 | U30: =SUM(P30:T30) -> 16.7 | V30: มี
A31: ORG-10 | B31: IAM | C31: ระบบจัดการผู้ใช้และสิทธิ์ (User & Permission) | D31: Role และ Permission | E31: Roles & permissions | F31: 08_Organization | ประกาศมาตรการความปลอดภัย พ.ศ. 2565 (การควบคุมการเข้าถึง) | G31: Must | H31: P0 | I31: role มาตรฐานตามชีต Roles_Permissions (seed ต่อ tenant), custom role, clone role, permission catalog สร้างจาก OpenAPI | J31: หน้า role + permission matrix แบบ checkbox แยกโมดูลและ action (C/R/U/D/A/P/E/X) | K31: สร้างหรือแก้ role แล้วสิทธิ์มีผลทันทีโดยไม่ต้อง deploy | L31: IAM-02 | M31: M | N31: M | O31: Y | P31: =IFERROR(VLOOKUP($M31,Assumptions!$A$15:$B$20,2,FALSE()),0) -> 5 | Q31: =IFERROR(VLOOKUP($N31,Assumptions!$A$15:$B$20,2,FALSE()),0) -> 5 | R31: =ROUND((P31+Q31)*Assumptions!$B$8,1) -> 1.2 | S31: =IF($O31="Y",ROUND(Q31*Assumptions!$B$9,1),0) -> 2 | T31: =ROUND((P31+Q31)*Assumptions!$B$10,1) -> 3.5 | U31: =SUM(P31:T31) -> 16.7 | V31: มี
A32: ORG-11 | B32: IAM | C32: ระบบจัดการผู้ใช้และสิทธิ์ (User & Permission) | D32: ขอบเขตข้อมูลตามหน่วยงาน | E32: Data scope | F32: 08_Organization | ประกาศมาตรการความปลอดภัย พ.ศ. 2565 | G32: Must | H32: P0 | I32: ผูก role assignment กับ scope (ทั้งกลุ่ม / บริษัท / ฝ่าย / แผนก / สาขา รวมหน่วยย่อย), resolver สร้าง filter ใน repository ทุก query (ltree ของโครงสร้างองค์กร), หลาย scope ต่อคน | J32: เลือก scope แบบ tree ขณะให้ role | K32: ผู้ใช้แผนก A เห็นเฉพาะข้อมูลแผนก A ทุก API (automated test) | L32: IAM-02, ORG-04 | M32: L | N32: S | O32: N | P32: =IFERROR(VLOOKUP($M32,Assumptions!$A$15:$B$20,2,FALSE()),0) -> 10 | Q32: =IFERROR(VLOOKUP($N32,Assumptions!$A$15:$B$20,2,FALSE()),0) -> 3 | R32: =ROUND((P32+Q32)*Assumptions!$B$8,1) -> 1.6 | S32: =IF($O32="Y",ROUND(Q32*Assumptions!$B$9,1),0) -> 0 | T32: =ROUND((P32+Q32)*Assumptions!$B$10,1) -> 4.6 | U32: =SUM(P32:T32) -> 19.2 | V32: มี
A33: ORG-14 | B33: IAM | C33: ระบบจัดการผู้ใช้และสิทธิ์ (User & Permission) | D33: Login นโยบายรหัสผ่าน และ MFA | E33: Authentication & MFA | F33: 08_Organization | ประกาศมาตรการความปลอดภัย พ.ศ. 2565 | G33: Must | H33: P0 | I33: ตั้ง password policy, brute-force lockout, ลืมรหัสผ่าน, MFA (TOTP, WebAuthn/passkey) ใน Keycloak ต่อ tenant; บังคับ MFA ตาม role (ตรวจ claim ที่ Go middleware) และ step-up MFA | J33: หน้าตั้งค่านโยบายความปลอดภัยของ tenant; theme หน้า login / ลืมรหัส / ตั้ง MFA | K33: ผิดครบจำนวนแล้วบัญชีถูกล็อกตามเวลาที่ตั้ง; role ที่บังคับ MFA เข้าไม่ได้ถ้าไม่ผ่าน MFA | L33: IAM-01 | M33: M | N33: S | O33: Y | P33: =IFERROR(VLOOKUP($M33,Assumptions!$A$15:$B$20,2,FALSE()),0) -> 5 | Q33: =IFERROR(VLOOKUP($N33,Assumptions!$A$15:$B$20,2,FALSE()),0) -> 3 | R33: =ROUND((P33+Q33)*Assumptions!$B$8,1) -> 1 | S33: =IF($O33="Y",ROUND(Q33*Assumptions!$B$9,1),0) -> 1.2 | T33: =ROUND((P33+Q33)*Assumptions!$B$10,1) -> 2.8 | U33: =SUM(P33:T33) -> 13 | V33: มี
A34: ORG-16 | B34: IAM | C34: ระบบจัดการผู้ใช้และสิทธิ์ (User & Permission) | D34: API Client และ Service account | E34: API credentials | F34: 08_Organization | ประกาศมาตรการความปลอดภัย พ.ศ. 2565 | G34: Must | H34: P0 | I34: OAuth2 client credentials (Keycloak service account), scope ต่อ client, ผูก tenant/ระบบ, หมุน secret, IP allowlist ที่ middleware, ปิด client ทันที | J34: หน้าจัดการ API client แสดง secret ครั้งเดียว | K34: client เรียกได้เฉพาะ scope ที่ได้รับ และจาก IP ที่อนุญาตเท่านั้น | L34: IAM-02 | M34: M | N34: S | O34: N | P34: =IFERROR(VLOOKUP($M34,Assumptions!$A$15:$B$20,2,FALSE()),0) -> 5 | Q34: =IFERROR(VLOOKUP($N34,Assumptions!$A$15:$B$20,2,FALSE()),0) -> 3 | R34: =ROUND((P34+Q34)*Assumptions!$B$8,1) -> 1 | S34: =IF($O34="Y",ROUND(Q34*Assumptions!$B$9,1),0) -> 0 | T34: =ROUND((P34+Q34)*Assumptions!$B$10,1) -> 2.8 | U34: =SUM(P34:T34) -> 11.8 | V34: มี
A35: ORG-19 | B35: IAM | C35: ระบบจัดการผู้ใช้และสิทธิ์ (User & Permission) | D35: Audit log | E35: Audit log | F35: 08_Organization | ประกาศมาตรการความปลอดภัย พ.ศ. 2565 | G35: Must | H35: P0 | I35: API ค้นหา / กรอง / ส่งออก audit log และตรวจ hash chain | J35: หน้าดู log ตามผู้ใช้ / โมดูล / ช่วงเวลา พร้อมรายละเอียด before/after | K35: ตรวจได้ว่าใครเปลี่ยนสิทธิ์ของใคร เมื่อไร และส่งออกได้ | L35: PLT-12 | M35: S | N35: M | O35: Y | P35: =IFERROR(VLOOKUP($M35,Assumptions!$A$15:$B$20,2,FALSE()),0) -> 3 | Q35: =IFERROR(VLOOKUP($N35,Assumptions!$A$15:$B$20,2,FALSE()),0) -> 5 | R35: =ROUND((P35+Q35)*Assumptions!$B$8,1) -> 1 | S35: =IF($O35="Y",ROUND(Q35*Assumptions!$B$9,1),0) -> 2 | T35: =ROUND((P35+Q35)*Assumptions!$B$10,1) -> 2.8 | U35: =SUM(P35:T35) -> 13.8 | V35: มี
A36: IAM-04 | B36: IAM | C36: ระบบจัดการผู้ใช้และสิทธิ์ (User & Permission) | D36: สิทธิ์ผู้ใช้ภายนอก (guest) | E36: External guest access | F36: เพิ่มโดย PM/SA | G36: Must | H36: P1 | I36: token แบบ magic link ผูกงานเดียว (แบบประเมิน / เอกสาร / แจ้งเหตุ / งานย่อย) มีวันหมดอายุ, OTP ยืนยันอีเมล, สิทธิ์เฉพาะงานนั้น, เพิกถอนได้ | J36: หน้า guest ใน portal สำหรับคู่ค้า ผู้ประมวลผล และผู้ร่วมประเมิน | K36: ลิงก์ใช้ได้เฉพาะงานที่เชิญ หมดอายุตามที่ตั้ง และเพิกถอนแล้วใช้ไม่ได้ทันที | L36: IAM-02 | M36: M | N36: S | O36: N | P36: =IFERROR(VLOOKUP($M36,Assumptions!$A$15:$B$20,2,FALSE()),0) -> 5 | Q36: =IFERROR(VLOOKUP($N36,Assumptions!$A$15:$B$20,2,FALSE()),0) -> 3 | R36: =ROUND((P36+Q36)*Assumptions!$B$8,1) -> 1 | S36: =IF($O36="Y",ROUND(Q36*Assumptions!$B$9,1),0) -> 0 | T36: =ROUND((P36+Q36)*Assumptions!$B$10,1) -> 2.8 | U36: =SUM(P36:T36) -> 11.8 | V36: - | W36: ใช้ร่วม VEN-05, DPIA-09, BRE-03, DSAR-12, DPA/DSA
A37: IAM-05 | B37: IAM | C37: ระบบจัดการผู้ใช้และสิทธิ์ (User & Permission) | D37: บริการยืนยันตัวตนเจ้าของข้อมูล | E37: Data subject verification service | F37: เพิ่มโดย PM/SA | G37: Must | H37: P1 | I37: OTP ทาง SMS / อีเมล, magic link, ตรวจกับข้อมูลที่มีในระบบ (match score), ระดับความมั่นใจต่อ use case, รองรับ IdP ภายนอก / ThaID ภายหลัง, rate limit กัน brute force | J37: ขั้นตอนยืนยันตัวตนใน portal ใช้ร่วม preference center, คำขอใช้สิทธิ และ double opt-in | K37: OTP หมดอายุใน 5 นาที จำกัดจำนวนครั้ง และบันทึกผลการยืนยันทุกครั้ง | L37: PLT-04 | M37: M | N37: S | O37: N | P37: =IFERROR(VLOOKUP($M37,Assumptions!$A$15:$B$20,2,FALSE()),0) -> 5 | Q37: =IFERROR(VLOOKUP($N37,Assumptions!$A$15:$B$20,2,FALSE()),0) -> 3 | R37: =ROUND((P37+Q37)*Assumptions!$B$8,1) -> 1 | S37: =IF($O37="Y",ROUND(Q37*Assumptions!$B$9,1),0) -> 0 | T37: =ROUND((P37+Q37)*Assumptions!$B$10,1) -> 2.8 | U37: =SUM(P37:T37) -> 11.8 | V37: - | W37: ใช้ร่วม CON-18, CON-19, CON-23, DSAR-06, DSAR-19
A38: ORG-12 | B38: IAM | C38: ระบบจัดการผู้ใช้และสิทธิ์ (User & Permission) | D38: กลุ่มผู้ใช้และทีม | E38: User groups & teams | F38: 08_Organization | แนวปฏิบัติตลาด | G38: Should | H38: P1 | I38: กลุ่มผู้ใช้สำหรับมอบหมายงานและให้สิทธิ์ทั้งกลุ่ม, ใช้เป็นผู้รับงานใน workflow | J38: หน้าจัดการกลุ่มและสมาชิก | K38: มอบหมายงานให้กลุ่มแล้วสมาชิกทุกคนเห็นงาน | L38: ORG-09 | M38: S | N38: S | O38: N | P38: =IFERROR(VLOOKUP($M38,Assumptions!$A$15:$B$20,2,FALSE()),0) -> 3 | Q38: =IFERROR(VLOOKUP($N38,Assumptions!$A$15:$B$20,2,FALSE()),0) -> 3 | R38: =ROUND((P38+Q38)*Assumptions!$B$8,1) -> 0.7 | S38: =IF($O38="Y",ROUND(Q38*Assumptions!$B$9,1),0) -> 0 | T38: =ROUND((P38+Q38)*Assumptions!$B$10,1) -> 2.1 | U38: =SUM(P38:T38) -> 8.8 | V38: มี | W38: ดึงเข้า P1 เพราะ workflow ของ DSAR / Breach มอบงานให้ทีม
A39: ORG-13 | B39: IAM | C39: ระบบจัดการผู้ใช้และสิทธิ์ (User & Permission) | D39: โปรไฟล์และการตั้งค่าส่วนตัว | E39: User profile | F39: 08_Organization | แนวปฏิบัติตลาด | G39: Should | H39: P1 | I39: API โปรไฟล์: ข้อมูลส่วนตัว รูป ภาษา ช่องทางรับแจ้งเตือน; ลิงก์ไปตั้งค่า MFA ใน Keycloak account | J39: หน้าโปรไฟล์และการตั้งค่าการแจ้งเตือน | K39: ผู้ใช้แก้ข้อมูลของตนได้โดยไม่ต้องขอผู้ดูแล | L39: ORG-09 | M39: S | N39: S | O39: N | P39: =IFERROR(VLOOKUP($M39,Assumptions!$A$15:$B$20,2,FALSE()),0) -> 3 | Q39: =IFERROR(VLOOKUP($N39,Assumptions!$A$15:$B$20,2,FALSE()),0) -> 3 | R39: =ROUND((P39+Q39)*Assumptions!$B$8,1) -> 0.7 | S39: =IF($O39="Y",ROUND(Q39*Assumptions!$B$9,1),0) -> 0 | T39: =ROUND((P39+Q39)*Assumptions!$B$10,1) -> 2.1 | U39: =SUM(P39:T39) -> 8.8 | V39: มี
A40: ORG-15 | B40: IAM | C40: ระบบจัดการผู้ใช้และสิทธิ์ (User & Permission) | D40: Single Sign-On และ ThaID | E40: SSO & ThaID | F40: 08_Organization | แนวปฏิบัติตลาด | G40: Should | H40: P1 | I40: identity brokering ใน Keycloak: OIDC/SAML (Entra ID, Google Workspace, ADFS), LDAP/AD federation, map group → role/scope, JIT provisioning; ThaID ผ่าน OIDC หลังขึ้นทะเบียน | J40: หน้าตั้งค่า IdP ต่อ tenant + ปุ่ม login ด้วย SSO / ThaID | K40: ผู้ใช้ Entra ID เข้าระบบได้และได้ role ตาม group; login ด้วย ThaID ผูกกับบัญชีเดิมได้ | L40: IAM-01 | M40: M | N40: S | O40: N | P40: =IFERROR(VLOOKUP($M40,Assumptions!$A$15:$B$20,2,FALSE()),0) -> 5 | Q40: =IFERROR(VLOOKUP($N40,Assumptions!$A$15:$B$20,2,FALSE()),0) -> 3 | R40: =ROUND((P40+Q40)*Assumptions!$B$8,1) -> 1 | S40: =IF($O40="Y",ROUND(Q40*Assumptions!$B$9,1),0) -> 0 | T40: =ROUND((P40+Q40)*Assumptions!$B$10,1) -> 2.8 | U40: =SUM(P40:T40) -> 11.8 | V40: มีบางส่วน | W40: ดึงเข้า P1: ลูกค้าองค์กรมักบังคับ SSO; ThaID ต้องขึ้นทะเบียน (R09)
A41: ORG-17 | B41: IAM | C41: ระบบจัดการผู้ใช้และสิทธิ์ (User & Permission) | D41: ปกปิดข้อมูลส่วนบุคคลบนหน้าจอ | E41: PII masking | F41: 08_Organization | ม.37(1) | G41: Should | H41: P1 | I41: masking policy ต่อฟิลด์ (เลขบัตร / เบอร์ / อีเมล) ใน response serializer, สิทธิ์ pii.unmask, endpoint unmask ต้องระบุเหตุผลและบันทึก audit | J41: component แสดงค่าปกปิด + ปุ่ม 'แสดง' พร้อมกล่องเหตุผล | K41: ผู้ไม่มีสิทธิ์ไม่ได้รับค่าจริงจาก API และการ unmask ทุกครั้งมี log | L41: IAM-02, PLT-13 | M41: M | N41: S | O41: N | P41: =IFERROR(VLOOKUP($M41,Assumptions!$A$15:$B$20,2,FALSE()),0) -> 5 | Q41: =IFERROR(VLOOKUP($N41,Assumptions!$A$15:$B$20,2,FALSE()),0) -> 3 | R41: =ROUND((P41+Q41)*Assumptions!$B$8,1) -> 1 | S41: =IF($O41="Y",ROUND(Q41*Assumptions!$B$9,1),0) -> 0 | T41: =ROUND((P41+Q41)*Assumptions!$B$10,1) -> 2.8 | U41: =SUM(P41:T41) -> 11.8 | V41: ไม่มี | W41: ดึงเข้า P1 ให้ทุกโมดูลใช้ตั้งแต่ต้น; OneTrust ไม่มี (จุดต่าง)
...

Sheet Task_List
A1: รายการ Task (พร้อม import เข้า Jira / Azure DevOps / GitHub Projects)
A2: วันทำงานดึงจาก WBS และ Project_Tasks อัตโนมัติ | ช่อง Sprint / ผู้รับผิดชอบ / สถานะ ใช้วางแผนและติดตาม
A4: Task ID | B4: Feature / งาน | C4: Epic | D4: ชื่องาน | E4: บทบาท | F4: วัน | G4: Phase | H4: Priority | I4: ขึ้นกับ | J4: Sprint | K4: ผู้รับผิดชอบ | L4: สถานะ
A5: PLT-01-SA | B5: PLT-01 | C5: PLT | D5: วิเคราะห์ business rules, ERD และ OpenAPI spec: โครงระบบ Go modular monolith + Next.js monorepo | E5: SA | F5: =WBS!R5 -> 1.8 | G5: =WBS!H5 -> P0 | H5: =WBS!G5 -> Must | I5: T04, T05 | L5: To Do
A6: PLT-01-BE | B6: PLT-01 | C6: PLT | D6: [Go] โครง backend/internal/<module>, chi router + oapi-codegen (OpenAPI-first), pgx + sqlc, goose migration, config, error model RFC 9457, health/readiness, graceful shutdown; binary api / worker / scanner | E6: BE | F6: =WBS!P5 -> 10 | G6: =WBS!H5 -> P0 | H6: =WBS!G5 -> Must | I6: PLT-01-SA | L6: To Do
A7: PLT-01-FE | B7: PLT-01 | C7: PLT | D7: [Next.js] Turborepo + pnpm: apps/admin, apps/portal (App Router, TypeScript), packages/ui (shadcn/ui + Tailwind), api-client generate จาก OpenAPI, layout และเมนูตามสิทธิ์ | E7: FE | F7: =WBS!Q5 -> 5 | G7: =WBS!H5 -> P0 | H7: =WBS!G5 -> Must | I7: PLT-01-SA | L7: To Do
A8: PLT-01-QA | B8: PLT-01 | C8: PLT | D8: test case + automated test: สร้างโมดูลใหม่จาก template ได้ภายใน 1 วัน; แก้ OpenAPI แล้ว Go stub และ TS client generate ใน CI | E8: QA | F8: =WBS!T5 -> 5.3 | G8: =WBS!H5 -> P0 | H8: =WBS!G5 -> Must | I8: PLT-01-BE, PLT-01-FE | L8: To Do
A9: PLT-02-SA | B9: PLT-02 | C9: PLT | D9: วิเคราะห์ business rules, ERD และ OpenAPI spec: Multi-tenant และการแยกข้อมูล | E9: SA | F9: =WBS!R6 -> 1.6 | G9: =WBS!H6 -> P0 | H9: =WBS!G6 -> Must | I9: PLT-01 | L9: To Do
A10: PLT-02-BE | B10: PLT-02 | C10: PLT | D10: [Go] tenant registry, resolver จาก subdomain / custom domain / token, tenant_id ทุกตาราง + PostgreSQL RLS (SET app.tenant_id ต่อ transaction), provisioning (master data, role มาตรฐาน), โหมด DB แยกต่อ tenant | E10: BE | F10: =WBS!P6 -> 10 | G10: =WBS!H6 -> P0 | H10: =WBS!G6 -> Must | I10: PLT-02-SA | L10: To Do
A11: PLT-02-FE | B11: PLT-02 | C11: PLT | D11: [Next.js] tenant context ใน middleware ของ Next.js, custom domain ของ portal | E11: FE | F11: =WBS!Q6 -> 3 | G11: =WBS!H6 -> P0 | H11: =WBS!G6 -> Must | I11: PLT-02-SA | L11: To Do
A12: PLT-02-QA | B12: PLT-02 | C12: PLT | D12: test case + automated test: ผู้ใช้ tenant A เข้าถึงข้อมูล tenant B ไม่ได้แม้เรียก API ตรง (automated test ทุก endpoint) | E12: QA | F12: =WBS!T6 -> 4.6 | G12: =WBS!H6 -> P0 | H12: =WBS!G6 -> Must | I12: PLT-02-BE, PLT-02-FE | L12: To Do
A13: PLT-03-SA | B13: PLT-03 | C13: PLT | D13: วิเคราะห์ business rules, ERD และ OpenAPI spec: ระบบหลายภาษา TH/EN | E13: SA | F13: =WBS!R7 -> 1 | G13: =WBS!H7 -> P0 | H13: =WBS!G7 -> Must | I13: PLT-01 | L13: To Do
A14: PLT-03-BE | B14: PLT-03 | C14: PLT | D14: [Go] ตาราง translation สำหรับเนื้อหาที่ผู้ใช้สร้าง (ข้อความยินยอม ประกาศ template), Accept-Language, fallback | E14: BE | F14: =WBS!P7 -> 3 | G14: =WBS!H7 -> P0 | H14: =WBS!G7 -> Must | I14: PLT-03-SA | L14: To Do
A15: PLT-03-FE | B15: PLT-03 | C15: PLT | D15: [Next.js] next-intl ข้อความ UI TH/EN, วันที่ พ.ศ. / ค.ศ., เขตเวลา Asia/Bangkok, ฟอนต์ไทย | E15: FE | F15: =WBS!Q7 -> 5 | G15: =WBS!H7 -> P0 | H15: =WBS!G7 -> Must | I15: PLT-03-SA | L15: To Do
A16: PLT-03-QA | B16: PLT-03 | C16: PLT | D16: test case + automated test: ทุกหน้าสลับ TH/EN ได้ และวันที่แสดง พ.ศ. ตามการตั้งค่า | E16: QA | F16: =WBS!T7 -> 2.8 | G16: =WBS!H7 -> P0 | H16: =WBS!G7 -> Must | I16: PLT-03-BE, PLT-03-FE | L16: To Do
A17: PLT-04-SA | B17: PLT-04 | C17: PLT | D17: วิเคราะห์ business rules, ERD และ OpenAPI spec: บริการแจ้งเตือน Email / SMS / LINE / In-app | E17: SA | F17: =WBS!R8 -> 1.8 | G17: =WBS!H8 -> P0 | H17: =WBS!G8 -> Must | I17: PLT-10 | L17: To Do
A18: PLT-04-UX | B18: PLT-04 | C18: PLT | D18: ออกแบบหน้าจอและ prototype: บริการแจ้งเตือน Email / SMS / LINE / In-app | E18: UX | F18: =WBS!S8 -> 2 | G18: =WBS!H8 -> P0 | H18: =WBS!G8 -> Must | I18: PLT-04-SA | L18: To Do
A19: PLT-04-BE | B19: PLT-04 | C19: PLT | D19: [Go] template มีตัวแปร (TH/EN), adapter SMTP/SES, SMS gateway ไทย, LINE Messaging API, in-app ผ่าน SSE, ส่งผ่าน River + retry, delivery log, quiet hours | E19: BE | F19: =WBS!P8 -> 10 | G19: =WBS!H8 -> P0 | H19: =WBS!G8 -> Must | I19: PLT-04-SA | L19: To Do
A20: PLT-04-FE | B20: PLT-04 | C20: PLT | D20: [Next.js] หน้าจัดการ template พร้อม preview, กระดิ่งแจ้งเตือนใน admin, หน้าสถานะการส่ง | E20: FE | F20: =WBS!Q8 -> 5 | G20: =WBS!H8 -> P0 | H20: =WBS!G8 -> Must | I20: PLT-04-UX | L20: To Do
A21: PLT-04-QA | B21: PLT-04 | C21: PLT | D21: test case + automated test: ส่งล้มเหลวมี retry อัตโนมัติ และตรวจสถานะรายข้อความได้ | E21: QA | F21: =WBS!T8 -> 5.3 | G21: =WBS!H8 -> P0 | H21: =WBS!G8 -> Must | I21: PLT-04-BE, PLT-04-FE | L21: To Do
A22: PLT-05-SA | B22: PLT-05 | C22: PLT | D22: วิเคราะห์ business rules, ERD และ OpenAPI spec: Workflow & SLA engine | E22: SA | F22: =WBS!R9 -> 3 | G22: =WBS!H9 -> P0 | H22: =WBS!G9 -> Must | I22: PLT-10, ORG-20 | L22: To Do
A23: PLT-05-UX | B23: PLT-05 | C23: PLT | D23: ออกแบบหน้าจอและ prototype: Workflow & SLA engine | E23: UX | F23: =WBS!S9 -> 2 | G23: =WBS!H9 -> P0 | H23: =WBS!G9 -> Must | I23: PLT-05-SA | L23: To Do
A24: PLT-05-BE | B24: PLT-05 | C24: PLT | D24: [Go] state machine กำหนดได้ต่อ tenant (JSON definition), มอบหมายคน/กลุ่ม, SLA timer แบบวันปฏิทิน / วันทำการ / ชั่วโมง พร้อมวันหยุดไทย, reminder และ escalation ด้วย River scheduled job, comment, history | E24: BE | F24: =WBS!P9 -> 20 | G24: =WBS!H9 -> P0 | H24: =WBS!G9 -> Must | I24: PLT-05-SA | L24: To Do
A25: PLT-05-FE | B25: PLT-05 | C25: PLT | D25: [Next.js] component กระดานงาน, timeline, ป้าย SLA, หน้าตั้งค่า workflow แบบฟอร์ม | E25: FE | F25: =WBS!Q9 -> 5 | G25: =WBS!H9 -> P0 | H25: =WBS!G9 -> Must | I25: PLT-05-UX | L25: To Do
A26: PLT-05-QA | B26: PLT-05 | C26: PLT | D26: test case + automated test: นับ SLA ถูกต้องเมื่อข้ามวันหยุด และแจ้งเตือนก่อนครบกำหนดตามที่ตั้ง (unit test ครอบคลุมกรณีข้ามวันหยุด) | E26: QA | F26: =WBS!T9 -> 8.8 | G26: =WBS!H9 -> P0 | H26: =WBS!G9 -> Must | I26: PLT-05-BE, PLT-05-FE | L26: To Do
A27: PLT-06-SA | B27: PLT-06 | C27: PLT | D27: วิเคราะห์ business rules, ERD และ OpenAPI spec: Form & assessment engine | E27: SA | F27: =WBS!R10 -> 3.6 | G27: =WBS!H10 -> P0 | H27: =WBS!G10 -> Must | I27: PLT-01 | L27: To Do
A28: PLT-06-UX | B28: PLT-06 | C28: PLT | D28: ออกแบบหน้าจอและ prototype: Form & assessment engine | E28: UX | F28: =WBS!S10 -> 8 | G28: =WBS!H10 -> P0 | H28: =WBS!G10 -> Must | I28: PLT-06-SA | L28: To Do
A29: PLT-06-BE | B29: PLT-06 | C29: PLT | D29: [Go] form schema มีเวอร์ชัน (JSON), ประเภทคำถาม, conditional logic, คะแนน/น้ำหนัก, validation ฝั่ง server, คำตอบ JSONB, มอบหมายผู้ตอบรายส่วน | E29: BE | F29: =WBS!P10 -> 10 | G29: =WBS!H10 -> P0 | H29: =WBS!G10 -> Must | I29: PLT-06-SA | L29: To Do
A30: PLT-06-FE | B30: PLT-06 | C30: PLT | D30: [Next.js] Form builder ลากวาง (dnd-kit) + renderer ใช้ร่วม admin และ portal (react-hook-form + zod), preview หลายภาษา | E30: FE | F30: =WBS!Q10 -> 20 | G30: =WBS!H10 -> P0 | H30: =WBS!G10 -> Must | I30: PLT-06-UX | L30: To Do
A31: PLT-06-QA | B31: PLT-06 | C31: PLT | D31: test case + automated test: สร้างแบบประเมินที่มีเงื่อนไขซ่อน/แสดงและคิดคะแนนได้โดยไม่เขียนโค้ด; ทุกโมดูลใช้ renderer เดียวกัน | E31: QA | F31: =WBS!T10 -> 10.5 | G31: =WBS!H10 -> P0 | H31: =WBS!G10 -> Must | I31: PLT-06-BE, PLT-06-FE | L31: To Do
A32: PLT-07-SA | B32: PLT-07 | C32: PLT | D32: วิเคราะห์ business rules, ERD และ OpenAPI spec: ความเห็น ไฟล์แนบ และไทม์ไลน์กิจกรรม | E32: SA | F32: =WBS!R11 -> 1.2 | G32: =WBS!H11 -> P0 | H32: =WBS!G11 -> Must | I32: PLT-09, PLT-12 | L32: To Do
A33: PLT-07-UX | B33: PLT-07 | C33: PLT | D33: ออกแบบหน้าจอและ prototype: ความเห็น ไฟล์แนบ และไทม์ไลน์กิจกรรม | E33: UX | F33: =WBS!S11 -> 2 | G33: =WBS!H11 -> P0 | H33: =WBS!G11 -> Must | I33: PLT-07-SA | L33: To Do
A34: PLT-07-BE | B34: PLT-07 | C34: PLT | D34: [Go] comment + @mention, ไฟล์แนบ, activity feed ต่อ record แบบ polymorphic, แจ้งเตือนผู้เกี่ยวข้อง | E34: BE | F34: =WBS!P11 -> 5 | G34: =WBS!H11 -> P0 | H34: =WBS!G11 -> Must | I34: PLT-07-SA | L34: To Do
A35: PLT-07-FE | B35: PLT-07 | C35: PLT | D35: [Next.js] component ความเห็น / ไฟล์แนบ / ไทม์ไลน์ ใช้ร่วมทุกโมดูล | E35: FE | F35: =WBS!Q11 -> 5 | G35: =WBS!H11 -> P0 | H35: =WBS!G11 -> Must | I35: PLT-07-UX | L35: To Do
A36: PLT-07-QA | B36: PLT-07 | C36: PLT | D36: test case + automated test: ทุกโมดูลใช้ component เดียวกัน และการ mention ส่งแจ้งเตือน | E36: QA | F36: =WBS!T11 -> 3.5 | G36: =WBS!H11 -> P0 | H36: =WBS!G11 -> Must | I36: PLT-07-BE, PLT-07-FE | L36: To Do
A37: PLT-08-SA | B37: PLT-08 | C37: PLT | D37: วิเคราะห์ business rules, ERD และ OpenAPI spec: เวอร์ชันและการอนุมัติ | E37: SA | F37: =WBS!R12 -> 1.2 | G37: =WBS!H12 -> P0 | H37: =WBS!G12 -> Must | I37: PLT-05, PLT-07 | L37: To Do
A38: PLT-08-UX | B38: PLT-08 | C38: PLT | D38: ออกแบบหน้าจอและ prototype: เวอร์ชันและการอนุมัติ | E38: UX | F38: =WBS!S12 -> 2 | G38: =WBS!H12 -> P0 | H38: =WBS!G12 -> Must | I38: PLT-08-SA | L38: To Do
A39: PLT-08-BE | B39: PLT-08 | C39: PLT | D39: [Go] snapshot + diff ของ record, สถานะ ร่าง → รอตรวจ → อนุมัติ → เผยแพร่, ผู้อนุมัติหลายระดับ, maker-checker | E39: BE | F39: =WBS!P12 -> 5 | G39: =WBS!H12 -> P0 | H39: =WBS!G12 -> Must | I39: PLT-08-SA | L39: To Do
A40: PLT-08-FE | B40: PLT-08 | C40: PLT | D40: [Next.js] แถบสถานะเวอร์ชัน, หน้าเปรียบเทียบเวอร์ชัน, กล่องงานรออนุมัติ | E40: FE | F40: =WBS!Q12 -> 5 | G40: =WBS!H12 -> P0 | H40: =WBS!G12 -> Must | I40: PLT-08-UX | L40: To Do
A41: PLT-08-QA | B41: PLT-08 | C41: PLT | D41: test case + automated test: record ที่เผยแพร่แล้วแก้ไม่ได้ต้องสร้างเวอร์ชันใหม่; ผู้สร้างอนุมัติงานของตนเองไม่ได้ | E41: QA | F41: =WBS!T12 -> 3.5 | G41: =WBS!H12 -> P0 | H41: =WBS!G12 -> Must | I41: PLT-08-BE, PLT-08-FE | L41: To Do
...

Sheet Project_Tasks
A1: งานโครงการและงานสนับสนุน (ไม่ใช่ฟีเจอร์)
A2: ช่องสีเหลืองคือ man-day ที่ประมาณ แก้ได้ | แถว T00 คำนวณจากจำนวน sprint ของแต่ละ phase
A4: ID | B4: Phase | C4: หมวด | D4: งาน | E4: ผลลัพธ์ (Deliverable) | F4: ขึ้นกับ | G4: PM | H4: SA | I4: UX | J4: BE | K4: FE | L4: QA | M4: DevOps | N4: Legal/DPO | O4: Doc | P4: รวม (วัน)
A5: T00-P0 | B5: P0 | C5: งานต่อเนื่อง | D5: บริหารโครงการ + DevOps ต่อเนื่อง Phase 0 (PM: ceremonies, status report, steering, risk/issue, change control; DevOps: environment, release, monitoring, on-call) | E5: รายงานสถานะ, release | F5: - | G5: =Roadmap!N5*Assumptions!$B$11 -> 18 | M5: =Roadmap!N5*Assumptions!$B$13 -> 30 | P5: =SUM(G5:O5) -> 48
A6: T00-P1 | B6: P1 | C6: งานต่อเนื่อง | D6: บริหารโครงการ + DevOps ต่อเนื่อง Phase 1 | E6: รายงานสถานะ, release | F6: - | G6: =Roadmap!N6*Assumptions!$B$11 -> 27 | M6: =Roadmap!N6*Assumptions!$B$13 -> 45 | P6: =SUM(G6:O6) -> 72
A7: T00-P2 | B7: P2 | C7: งานต่อเนื่อง | D7: บริหารโครงการ + DevOps ต่อเนื่อง Phase 2 | E7: รายงานสถานะ, release | F7: - | G7: =Roadmap!N7*Assumptions!$B$11 -> 15 | M7: =Roadmap!N7*Assumptions!$B$13 -> 25 | P7: =SUM(G7:O7) -> 40
A8: T00-P3 | B8: P3 | C8: งานต่อเนื่อง | D8: บริหารโครงการ + DevOps ต่อเนื่อง Phase 3 | E8: รายงานสถานะ, release | F8: - | G8: =Roadmap!N8*Assumptions!$B$11 -> 24 | M8: =Roadmap!N8*Assumptions!$B$13 -> 40 | P8: =SUM(G8:O8) -> 64
A9: T00-P4 | B9: P4 | C9: งานต่อเนื่อง | D9: บริหารโครงการ + DevOps ต่อเนื่อง Phase 4 | E9: รายงานสถานะ, release | F9: - | G9: =Roadmap!N9*Assumptions!$B$11 -> 12 | M9: =Roadmap!N9*Assumptions!$B$13 -> 20 | P9: =SUM(G9:O9) -> 32
A10: T01 | B10: P0 | C10: บริหารโครงการ | D10: Kickoff, project charter, RACI และแผนการสื่อสาร | E10: Charter, RACI | F10: - | G10: 5 | H10: 1 | P10: =SUM(G10:O10) -> 6
A11: T02 | B11: P0 | C11: วิเคราะห์ | D11: Workshop ความต้องการกับ DPO / กฎหมาย / ธุรกิจ ครบ 15 โมดูล + User & Permission | E11: User stories, requirement notes | F11: T01 | G11: 8 | H11: 16 | I11: 4 | N11: 8 | P11: =SUM(G11:O11) -> 36
A12: T03 | B12: P0 | C12: วิเคราะห์ | D12: วิเคราะห์ระบบ Consent เดิม (.NET, FSD V3.2): business rules, domain model, test case และแผนย้ายข้อมูลมาระบบ Go | E12: Reuse & migration plan | F12: T02 | H12: 5 | J12: 3 | L12: 2 | P12: =SUM(G12:O12) -> 10
A13: T04 | B13: P0 | C13: สถาปัตยกรรม | D13: Solution Architecture Document, NFR และ ADR (Next.js, Go, PostgreSQL, Keycloak, River, Gotenberg) + ตรวจ license ของ open source ทุกตัว | E13: SAD, NFR, ADR | F13: T02 | H13: 8 | J13: 4 | K13: 2 | M13: 2 | P13: =SUM(G13:O13) -> 16
A14: T05 | B14: P0 | C14: สถาปัตยกรรม | D14: ERD, data dictionary และมาตรฐาน OpenAPI (naming, error RFC 9457, pagination, x-permission) | E14: ERD, API guideline | F14: T04 | H14: 8 | J14: 4 | P14: =SUM(G14:O14) -> 12
A15: T06 | B15: P0 | C15: วิเคราะห์ | D15: ยืนยันโมเดลสิทธิ์ (Role / Permission / Data scope / Guest) กับลูกค้า | E15: ชีต Roles_Permissions ฉบับอนุมัติ | F15: T02 | G15: 1 | H15: 3 | N15: 1 | P15: =SUM(G15:O15) -> 5
A16: T07 | B16: P0 | C16: UX | D16: Design system (shadcn/ui + Tailwind), information architecture และ prototype หน้าหลักของ admin และ portal | E16: Figma + UI kit | F16: T02 | H16: 2 | I16: 12 | K16: 3 | P16: =SUM(G16:O16) -> 17
A17: T08 | B17: P0 | C17: บริหารโครงการ | D17: Product backlog, release plan, Definition of Ready / Done และประมาณการรอบแรก | E17: Backlog, release plan | F17: T02 | G17: 4 | H17: 4 | P17: =SUM(G17:O17) -> 8
A18: T09 | B18: P0 | C18: Infra & DevOps | D18: Environment Dev / SIT / UAT / Prod บน Kubernetes + IaC (OpenTofu/Terraform) + PostgreSQL HA, Valkey, object storage, Keycloak | E18: Environments | F18: T04 | M18: 10 | P18: =SUM(G18:O18) -> 10
A19: T10 | B19: P0 | C19: Infra & DevOps | D19: CI/CD: golangci-lint, ESLint, unit test, SAST (gosec/Semgrep), govulncheck/OSV-Scanner, Trivy, SBOM (Syft), image signing (cosign), GitOps deploy | E19: Pipeline | F19: T09 | J19: 1 | K19: 1 | M19: 6 | P19: =SUM(G19:O19) -> 8
A20: T11 | B20: P0 | C20: ทดสอบ | D20: Test strategy และ test plan | E20: Test plan | F20: T02 | L20: 4 | P20: =SUM(G20:O20) -> 4
A21: T12 | B21: P0 | C21: ทดสอบ | D21: Test automation framework: Go integration test (testcontainers-go), API contract test จาก OpenAPI, Playwright E2E, k6 | E21: Automation framework | F21: T11 | J21: 2 | L21: 10 | P21: =SUM(G21:O21) -> 12
A22: T13 | B22: P0 | C22: สถาปัตยกรรม | D22: PoC ความเสี่ยงเทคนิค: Keycloak multi-tenant + theme, cookie scanner (chromedp), PDF/DOCX ภาษาไทย, OCR และตรวจจับ PII ภาษาไทย | E22: PoC report | F22: T04 | H22: 3 | J22: 10 | K22: 3 | P22: =SUM(G22:O22) -> 16
A23: T14 | B23: P0 | C23: Security | D23: Threat modeling (STRIDE) และ security requirements ของแพลตฟอร์ม | E23: Threat model | F23: T04 | H23: 3 | J23: 2 | M23: 1 | P23: =SUM(G23:O23) -> 6
A24: T15 | B24: P1 | C24: กฎหมาย | D24: เนื้อหาชุด P1 (TH/EN): template ประกาศ 8 กลุ่ม, ข้อความยินยอม, หนังสือตอบคำขอ, แบบแจ้ง สคส., กิจกรรมมาตรฐานราว 50 รายการ, checklist มาตรการความปลอดภัย | E24: Legal content P1 | F24: T02 | N24: 20 | P24: =SUM(G24:O24) -> 20
A25: T16 | B25: P1 | C25: วิเคราะห์ | D25: Integration specification: CRM / POS / LINE OA / Email / SMS gateway / SSO (Entra ID, Google) / ThaID | E25: Integration spec | F25: T04 | H25: 5 | J25: 2 | P25: =SUM(G25:O25) -> 7
A26: T17 | B26: P1 | C26: Infra & DevOps | D26: Production บน cloud ที่มี data center ในไทย + CDN สำหรับ cookie SDK + WAF + Helm chart | E26: Production | F26: T09 | M26: 8 | P26: =SUM(G26:O26) -> 8
A27: T18 | B27: P1 | C27: Infra & DevOps | D27: Monitoring / logging / alert (ร่วมกับ PLT-19) + on-call runbook | E27: Dashboards, runbook | F27: T17 | M27: 3 | P27: =SUM(G27:O27) -> 3
A28: T19 | B28: P1 | C28: Infra & DevOps | D28: Backup, PITR, DR + ทดสอบ restore | E28: DR runbook | F28: T17 | M28: 4 | P28: =SUM(G28:O28) -> 4
A29: T20 | B29: P1 | C29: Security | D29: Security hardening: TLS, CSP, secret ใน KMS/OpenBao, network policy, hardening Keycloak | E29: Hardening checklist | F29: T17 | J29: 1 | M29: 4 | P29: =SUM(G29:O29) -> 5
A30: T21 | B30: P1 | C30: ทดสอบ | D30: SIT รอบรวม Phase 1 | E30: SIT report | F30: ฟีเจอร์ P1 | J30: 3 | K30: 3 | L30: 12 | P30: =SUM(G30:O30) -> 18
A31: T22 | B31: P1 | C31: ทดสอบ | D31: Performance / load test (k6): Consent API, config แบนเนอร์ผ่าน CDN, portal | E31: Performance report | F31: T21 | J31: 3 | L31: 5 | M31: 2 | P31: =SUM(G31:O31) -> 10
A32: T23 | B32: P1 | C32: Security | D32: Security test (SAST/DAST ด้วย OWASP ZAP, OWASP Top 10, ทดสอบการแยก tenant) + แก้ไข | E32: Security test report | F32: T21 | J32: 5 | K32: 2 | L32: 4 | P32: =SUM(G32:O32) -> 11
A33: T24 | B33: P1 | C33: Security | D33: Penetration test โดยบุคคลภายนอก + retest (ค่าบริการแยก) | E33: Pentest report | F33: T23 | G33: 1 | J33: 5 | K33: 2 | P33: =SUM(G33:O33) -> 8
A34: T25 | B34: P1 | C34: ทดสอบ | D34: UAT Phase 1 (เตรียมข้อมูล ประสานงาน แก้ไข) | E34: UAT sign-off | F34: T21 | G34: 5 | H34: 3 | J34: 3 | K34: 3 | L34: 6 | P34: =SUM(G34:O34) -> 20
A35: T26 | B35: P1 | C35: ย้ายข้อมูล | D35: ย้ายข้อมูลความยินยอมจากระบบ Consent เดิมและ RoPA จาก Excel (ใช้ CON-22, ROPA-18) + reconcile | E35: Migration report | F35: T25 | H35: 2 | J35: 5 | L35: 3 | P35: =SUM(G35:O35) -> 10
A36: T27 | B36: P1 | C36: เอกสาร/อบรม | D36: คู่มือผู้ใช้และผู้ดูแลระบบ TH/EN | E36: User & admin guide | F36: T25 | H36: 2 | O36: 10 | P36: =SUM(G36:O36) -> 12
A37: T28 | B37: P1 | C37: เอกสาร/อบรม | D37: เอกสาร API + ตัวอย่างติดตั้ง cookie SDK และ Consent API | E37: Developer docs | F37: CON-16 | J37: 3 | K37: 2 | P37: =SUM(G37:O37) -> 5
A38: T29 | B38: P1 | C38: เอกสาร/อบรม | D38: อบรมผู้ใช้ + Train the trainer | E38: Training | F38: T27 | G38: 2 | H38: 3 | P38: =SUM(G38:O38) -> 5
A39: T30 | B39: P1 | C39: กฎหมาย | D39: Legal review ตามประกาศ สคส. ล่าสุด ก่อน go-live Phase 1 | E39: Legal sign-off | F39: T25 | N39: 3 | P39: =SUM(G39:O39) -> 3
